08/18/19 21:19:50       Matched 1.0 condor1@cloud.univalle.edu.co <45.5.164.207:443?PrivAddr=%3c192.168.28.55:443%3fsock%3d79_147a_5%3e&PrivNet=univalle.edu.co&addrs=45.5.164.207-443&noUDP&sock=79_147a_5> preempting none <45.5.164.207:9620?PrivAddr=%3c192.168.28.56:9620%3fsock%3d77_b549_3%3e&PrivNet=univalle.edu.co&addrs=45.5.164.207-9620&noUDP&sock=77_b549_3> slot1@edier-worker-1.cloud.univalle.edu.co
08/18/19 22:23:36       Matched 2.0 condor1@cloud.univalle.edu.co <45.5.164.207:443?PrivAddr=%3c192.168.28.55:443%3fsock%3d79_147a_5%3e&PrivNet=univalle.edu.co&addrs=45.5.164.207-443&noUDP&sock=79_147a_5> preempting none <45.5.164.207:9620?PrivAddr=%3c192.168.28.56:9620%3fsock%3d77_b549_3%3e&PrivNet=univalle.edu.co&addrs=45.5.164.207-9620&noUDP&sock=77_b549_3> slot1@edier-worker-1.cloud.univalle.edu.co
08/18/19 22:23:36       Rejected 2.0 condor1@cloud.univalle.edu.co <45.5.164.207:443?PrivAddr=%3c192.168.28.55:443%3fsock%3d79_147a_5%3e&PrivNet=univalle.edu.co&addrs=45.5.164.207-443&noUDP&sock=79_147a_5>: no match found
08/18/19 22:29:18       Rejected 3.0 condor1@cloud.univalle.edu.co <45.5.164.207:443?PrivAddr=%3c192.168.28.55:443%3fsock%3d79_147a_5%3e&PrivNet=univalle.edu.co&addrs=45.5.164.207-443&noUDP&sock=79_147a_5>: no match found
08/18/19 22:31:38       Rejected 4.0 condor1@cloud.univalle.edu.co <45.5.164.207:443?PrivAddr=%3c192.168.28.55:443%3fsock%3d79_147a_5%3e&PrivNet=univalle.edu.co&addrs=45.5.164.207-443&noUDP&sock=79_147a_5>: no match found
08/18/19 22:32:38       Rejected 4.0 condor1@cloud.univalle.edu.co <45.5.164.207:443?PrivAddr=%3c192.168.28.55:443%3fsock%3d79_147a_5%3e&PrivNet=univalle.edu.co&addrs=45.5.164.207-443&noUDP&sock=79_147a_5>: no match found
08/18/19 22:33:38       Rejected 4.0 condor1@cloud.univalle.edu.co <45.5.164.207:443?PrivAddr=%3c192.168.28.55:443%3fsock%3d79_147a_5%3e&PrivNet=univalle.edu.co&addrs=45.5.164.207-443&noUDP&sock=79_147a_5>: no match found
08/18/19 22:34:39       Rejected 4.0 condor1@cloud.univalle.edu.co <45.5.164.207:443?PrivAddr=%3c192.168.28.55:443%3fsock%3d79_147a_5%3e&PrivNet=univalle.edu.co&addrs=45.5.164.207-443&noUDP&sock=79_147a_5>: no match found
08/18/19 22:35:38       Rejected 4.0 condor1@cloud.univalle.edu.co <45.5.164.207:443?PrivAddr=%3c192.168.28.55:443%3fsock%3d79_147a_5%3e&PrivNet=univalle.edu.co&addrs=45.5.164.207-443&noUDP&sock=79_147a_5>: no match found
08/18/19 22:36:38       Rejected 4.0 condor1@cloud.univalle.edu.co <45.5.164.207:443?PrivAddr=%3c192.168.28.55:443%3fsock%3d79_147a_5%3e&PrivNet=univalle.edu.co&addrs=45.5.164.207-443&noUDP&sock=79_147a_5>: no match found
08/18/19 22:37:38       Rejected 4.0 condor1@cloud.univalle.edu.co <45.5.164.207:443?PrivAddr=%3c192.168.28.55:443%3fsock%3d79_147a_5%3e&PrivNet=univalle.edu.co&addrs=45.5.164.207-443&noUDP&sock=79_147a_5>: no match found
08/18/19 22:38:38       Rejected 4.0 condor1@cloud.univalle.edu.co <45.5.164.207:443?PrivAddr=%3c192.168.28.55:443%3fsock%3d79_147a_5%3e&PrivNet=univalle.edu.co&addrs=45.5.164.207-443&noUDP&sock=79_147a_5>: no match found
08/18/19 22:39:38       Rejected 4.0 condor1@cloud.univalle.edu.co <45.5.164.207:443?PrivAddr=%3c192.168.28.55:443%3fsock%3d79_147a_5%3e&PrivNet=univalle.edu.co&addrs=45.5.164.207-443&noUDP&sock=79_147a_5>: no match found
08/18/19 22:56:58       Rejected 5.0 condor1@cloud.univalle.edu.co <45.5.164.207:443?PrivAddr=%3c192.168.28.55:443%3fsock%3d79_147a_5%3e&PrivNet=univalle.edu.co&addrs=45.5.164.207-443&noUDP&sock=79_147a_5>: no match found
08/18/19 22:57:58       Rejected 5.0 condor1@cloud.univalle.edu.co <45.5.164.207:443?PrivAddr=%3c192.168.28.55:443%3fsock%3d79_147a_5%3e&PrivNet=univalle.edu.co&addrs=45.5.164.207-443&noUDP&sock=79_147a_5>: no match found
08/18/19 22:58:58       Rejected 5.0 condor1@cloud.univalle.edu.co <45.5.164.207:443?PrivAddr=%3c192.168.28.55:443%3fsock%3d79_147a_5%3e&PrivNet=univalle.edu.co&addrs=45.5.164.207-443&noUDP&sock=79_147a_5>: no match found
08/18/19 22:59:18       Rejected 5.0 condor1@cloud.univalle.edu.co <45.5.164.207:443?PrivAddr=%3c192.168.28.55:443%3fsock%3d79_147a_5%3e&PrivNet=univalle.edu.co&addrs=45.5.164.207-443&noUDP&sock=79_147a_5>: no match found
08/18/19 22:59:18       Rejected 6.0 condor1@cloud.univalle.edu.co <45.5.164.207:443?PrivAddr=%3c192.168.28.55:443%3fsock%3d79_147a_5%3e&PrivNet=univalle.edu.co&addrs=45.5.164.207-443&noUDP&sock=79_147a_5>: no match found
08/18/19 23:00:18       Rejected 5.0 condor1@cloud.univalle.edu.co <45.5.164.207:443?PrivAddr=%3c192.168.28.55:443%3fsock%3d79_147a_5%3e&PrivNet=univalle.edu.co&addrs=45.5.164.207-443&noUDP&sock=79_147a_5>: no match found
08/18/19 23:00:18       Rejected 6.0 condor1@cloud.univalle.edu.co <45.5.164.207:443?PrivAddr=%3c192.168.28.55:443%3fsock%3d79_147a_5%3e&PrivNet=univalle.edu.co&addrs=45.5.164.207-443&noUDP&sock=79_147a_5>: no match found
08/18/19 23:01:18       Rejected 5.0 condor1@cloud.univalle.edu.co <45.5.164.207:443?PrivAddr=%3c192.168.28.55:443%3fsock%3d79_147a_5%3e&PrivNet=univalle.edu.co&addrs=45.5.164.207-443&noUDP&sock=79_147a_5>: no match found
08/18/19 23:01:18       Rejected 6.0 condor1@cloud.univalle.edu.co <45.5.164.207:443?PrivAddr=%3c192.168.28.55:443%3fsock%3d79_147a_5%3e&PrivNet=univalle.edu.co&addrs=45.5.164.207-443&noUDP&sock=79_147a_5>: no match found
08/18/19 23:03:06       Rejected 7.0 condor1@cloud.univalle.edu.co <45.5.164.207:443?PrivAddr=%3c192.168.28.55:443%3fsock%3d79_147a_5%3e&PrivNet=univalle.edu.co&addrs=45.5.164.207-443&noUDP&sock=79_147a_5>: no match found
08/18/19 23:04:09       Rejected 7.0 condor1@cloud.univalle.edu.co <45.5.164.207:443?PrivAddr=%3c192.168.28.55:443%3fsock%3d79_147a_5%3e&PrivNet=univalle.edu.co&addrs=45.5.164.207-443&noUDP&sock=79_147a_5>: no match found
08/18/19 23:05:06       Rejected 7.0 condor1@cloud.univalle.edu.co <45.5.164.207:443?PrivAddr=%3c192.168.28.55:443%3fsock%3d79_147a_5%3e&PrivNet=univalle.edu.co&addrs=45.5.164.207-443&noUDP&sock=79_147a_5>: no match found
08/18/19 23:06:06       Rejected 7.0 condor1@cloud.univalle.edu.co <45.5.164.207:443?PrivAddr=%3c192.168.28.55:443%3fsock%3d79_147a_5%3e&PrivNet=univalle.edu.co&addrs=45.5.164.207-443&noUDP&sock=79_147a_5>: no match found
08/18/19 23:07:07       Rejected 7.0 condor1@cloud.univalle.edu.co <45.5.164.207:443?PrivAddr=%3c192.168.28.55:443%3fsock%3d79_147a_5%3e&PrivNet=univalle.edu.co&addrs=45.5.164.207-443&noUDP&sock=79_147a_5>: no match found
08/18/19 23:08:06       Rejected 7.0 condor1@cloud.univalle.edu.co <45.5.164.207:443?PrivAddr=%3c192.168.28.55:443%3fsock%3d79_147a_5%3e&PrivNet=univalle.edu.co&addrs=45.5.164.207-443&noUDP&sock=79_147a_5>: no match found
08/18/19 23:09:06       Rejected 7.0 condor1@cloud.univalle.edu.co <45.5.164.207:443?PrivAddr=%3c192.168.28.55:443%3fsock%3d79_147a_5%3e&PrivNet=univalle.edu.co&addrs=45.5.164.207-443&noUDP&sock=79_147a_5>: no match found
08/18/19 23:10:06       Rejected 7.0 condor1@cloud.univalle.edu.co <45.5.164.207:443?PrivAddr=%3c192.168.28.55:443%3fsock%3d79_147a_5%3e&PrivNet=univalle.edu.co&addrs=45.5.164.207-443&noUDP&sock=79_147a_5>: no match found
08/18/19 23:11:06       Rejected 7.0 condor1@cloud.univalle.edu.co <45.5.164.207:443?PrivAddr=%3c192.168.28.55:443%3fsock%3d79_147a_5%3e&PrivNet=univalle.edu.co&addrs=45.5.164.207-443&noUDP&sock=79_147a_5>: no match found
08/18/19 23:12:06       Rejected 7.0 condor1@cloud.univalle.edu.co <45.5.164.207:443?PrivAddr=%3c192.168.28.55:443%3fsock%3d79_147a_5%3e&PrivNet=univalle.edu.co&addrs=45.5.164.207-443&noUDP&sock=79_147a_5>: no match found
08/18/19 23:13:07       Rejected 7.0 condor1@cloud.univalle.edu.co <45.5.164.207:443?PrivAddr=%3c192.168.28.55:443%3fsock%3d79_147a_5%3e&PrivNet=univalle.edu.co&addrs=45.5.164.207-443&noUDP&sock=79_147a_5>: no match found
08/18/19 23:15:31       Matched 8.0 condor1@cloud.univalle.edu.co <45.5.164.207:443?PrivAddr=%3c192.168.28.55:443%3fsock%3d79_147a_5%3e&PrivNet=univalle.edu.co&addrs=45.5.164.207-443&noUDP&sock=79_147a_5> preempting none <45.5.164.207:9620?PrivAddr=%3c192.168.28.56:9620%3fsock%3d77_b549_3%3e&PrivNet=univalle.edu.co&addrs=45.5.164.207-9620&noUDP&sock=77_b549_3> slot1@edier-worker-1.cloud.univalle.edu.co
08/18/19 23:15:31       Rejected 8.0 condor1@cloud.univalle.edu.co <45.5.164.207:443?PrivAddr=%3c192.168.28.55:443%3fsock%3d79_147a_5%3e&PrivNet=univalle.edu.co&addrs=45.5.164.207-443&noUDP&sock=79_147a_5>: no match found
08/18/19 23:16:31       Rejected 8.8 condor1@cloud.univalle.edu.co <45.5.164.207:443?PrivAddr=%3c192.168.28.55:443%3fsock%3d79_147a_5%3e&PrivNet=univalle.edu.co&addrs=45.5.164.207-443&noUDP&sock=79_147a_5>: no match found
08/18/19 23:17:31       Rejected 8.8 condor1@cloud.univalle.edu.co <45.5.164.207:443?PrivAddr=%3c192.168.28.55:443%3fsock%3d79_147a_5%3e&PrivNet=univalle.edu.co&addrs=45.5.164.207-443&noUDP&sock=79_147a_5>: no match found
08/18/19 23:18:31       Rejected 8.8 condor1@cloud.univalle.edu.co <45.5.164.207:443?PrivAddr=%3c192.168.28.55:443%3fsock%3d79_147a_5%3e&PrivNet=univalle.edu.co&addrs=45.5.164.207-443&noUDP&sock=79_147a_5>: no match found
08/18/19 23:19:31       Rejected 8.8 condor1@cloud.univalle.edu.co <45.5.164.207:443?PrivAddr=%3c192.168.28.55:443%3fsock%3d79_147a_5%3e&PrivNet=univalle.edu.co&addrs=45.5.164.207-443&noUDP&sock=79_147a_5>: no match found
08/18/19 23:20:31       Rejected 8.8 condor1@cloud.univalle.edu.co <45.5.164.207:443?PrivAddr=%3c192.168.28.55:443%3fsock%3d79_147a_5%3e&PrivNet=univalle.edu.co&addrs=45.5.164.207-443&noUDP&sock=79_147a_5>: no match found
08/18/19 23:21:32       Rejected 8.8 condor1@cloud.univalle.edu.co <45.5.164.207:443?PrivAddr=%3c192.168.28.55:443%3fsock%3d79_147a_5%3e&PrivNet=univalle.edu.co&addrs=45.5.164.207-443&noUDP&sock=79_147a_5>: no match found
08/18/19 23:22:31       Rejected 8.12 condor1@cloud.univalle.edu.co <45.5.164.207:443?PrivAddr=%3c192.168.28.55:443%3fsock%3d79_147a_5%3e&PrivNet=univalle.edu.co&addrs=45.5.164.207-443&noUDP&sock=79_147a_5>: no match found
08/18/19 23:23:31       Rejected 8.16 condor1@cloud.univalle.edu.co <45.5.164.207:443?PrivAddr=%3c192.168.28.55:443%3fsock%3d79_147a_5%3e&PrivNet=univalle.edu.co&addrs=45.5.164.207-443&noUDP&sock=79_147a_5>: no match found
08/18/19 23:24:31       Rejected 8.16 condor1@cloud.univalle.edu.co <45.5.164.207:443?PrivAddr=%3c192.168.28.55:443%3fsock%3d79_147a_5%3e&PrivNet=univalle.edu.co&addrs=45.5.164.207-443&noUDP&sock=79_147a_5>: no match found
08/18/19 23:25:31       Rejected 8.16 condor1@cloud.univalle.edu.co <45.5.164.207:443?PrivAddr=%3c192.168.28.55:443%3fsock%3d79_147a_5%3e&PrivNet=univalle.edu.co&addrs=45.5.164.207-443&noUDP&sock=79_147a_5>: no match found
08/18/19 23:26:31       Rejected 8.16 condor1@cloud.univalle.edu.co <45.5.164.207:443?PrivAddr=%3c192.168.28.55:443%3fsock%3d79_147a_5%3e&PrivNet=univalle.edu.co&addrs=45.5.164.207-443&noUDP&sock=79_147a_5>: no match found
08/18/19 23:27:31       Rejected 8.16 condor1@cloud.univalle.edu.co <45.5.164.207:443?PrivAddr=%3c192.168.28.55:443%3fsock%3d79_147a_5%3e&PrivNet=univalle.edu.co&addrs=45.5.164.207-443&noUDP&sock=79_147a_5>: no match found
08/18/19 23:28:31       Rejected 8.16 condor1@cloud.univalle.edu.co <45.5.164.207:443?PrivAddr=%3c192.168.28.55:443%3fsock%3d79_147a_5%3e&PrivNet=univalle.edu.co&addrs=45.5.164.207-443&noUDP&sock=79_147a_5>: no match found
08/19/19 00:00:54       Matched 5.4 condor1@cloud.uniandes.edu.co <157.253.205.92:60403?addrs=157.253.205.92-60403> preempting none <45.5.164.207:9620?PrivAddr=%3c192.168.28.56:9620%3fsock%3d77_b549_3%3e&PrivNet=univalle.edu.co&addrs=45.5.164.207-9620&noUDP&sock=77_b549_3> slot1@edier-worker-1.cloud.univalle.edu.co
08/19/19 00:00:54       Rejected 5.4 condor1@cloud.uniandes.edu.co <157.253.205.92:60403?addrs=157.253.205.92-60403>: no match found
08/19/19 00:01:55       Rejected 5.8 condor1@cloud.uniandes.edu.co <157.253.205.92:60403?addrs=157.253.205.92-60403>: no match found
08/19/19 00:02:54       Rejected 5.8 condor1@cloud.uniandes.edu.co <157.253.205.92:60403?addrs=157.253.205.92-60403>: no match found
08/19/19 00:03:54       Rejected 5.8 condor1@cloud.uniandes.edu.co <157.253.205.92:60403?addrs=157.253.205.92-60403>: no match found
08/19/19 00:04:54       Rejected 5.8 condor1@cloud.uniandes.edu.co <157.253.205.92:60403?addrs=157.253.205.92-60403>: no match found
08/19/19 00:05:55       Rejected 5.8 condor1@cloud.uniandes.edu.co <157.253.205.92:60403?addrs=157.253.205.92-60403>: no match found
08/19/19 00:06:54       Rejected 5.8 condor1@cloud.uniandes.edu.co <157.253.205.92:60403?addrs=157.253.205.92-60403>: no match found
08/19/19 00:07:54       Rejected 5.16 condor1@cloud.uniandes.edu.co <157.253.205.92:60403?addrs=157.253.205.92-60403>: no match found
08/19/19 00:08:54       Rejected 5.16 condor1@cloud.uniandes.edu.co <157.253.205.92:60403?addrs=157.253.205.92-60403>: no match found
08/19/19 00:09:54       Rejected 5.16 condor1@cloud.uniandes.edu.co <157.253.205.92:60403?addrs=157.253.205.92-60403>: no match found
08/19/19 00:10:54       Rejected 5.16 condor1@cloud.uniandes.edu.co <157.253.205.92:60403?addrs=157.253.205.92-60403>: no match found
08/19/19 00:11:55       Rejected 5.16 condor1@cloud.uniandes.edu.co <157.253.205.92:60403?addrs=157.253.205.92-60403>: no match found
08/19/19 00:12:54       Rejected 5.16 condor1@cloud.uniandes.edu.co <157.253.205.92:60403?addrs=157.253.205.92-60403>: no match found
08/19/19 00:13:54       Rejected 5.16 condor1@cloud.uniandes.edu.co <157.253.205.92:60403?addrs=157.253.205.92-60403>: no match found
